<?xml version="1.0"?>
<sdf version='1.7'>
  <model name='spok'>
    <link name='base_link'>
      <inertial>
        <pose>0 0 0.000288 0 -0 0</pose>
        <mass>2.43</mass>
        <inertia>
          <ixx>0.157124</ixx>
          <ixy>0</ixy>
          <ixz>0</ixz>
          <iyy>0.158124</iyy>
          <iyz>0</iyz>
          <izz>0.1591</izz>
        </inertia>
      </inertial>
      <collision name='base_link_collision'>
        <pose>-0.045 -0.06 -0.015 0 -0 0</pose>
        <geometry>
          <mesh>
            <scale>0.001 0.001 0.001</scale>
            <uri>file://$(find quadruped_robot)/stl/mainbody.stl</uri>
          </mesh>
        </geometry>
        <surface>
          <contact>
            <ode/>
          </contact>
          <friction>
            <ode/>
          </friction>
        </surface>
      </collision>
      <collision name='base_link_fixed_joint_lump__front_link_collision_1'>
        <pose>-0.04 -0.06 -0.014 0 -0 0</pose>
        <geometry>
          <mesh>
            <scale>0.001 0.001 0.001</scale>
            <uri>file://$(find quadruped_robot)/stl/frontpart.stl</uri>
          </mesh>
        </geometry>
        <surface>
          <contact>
            <ode/>
          </contact>
          <friction>
            <ode/>
          </friction>
        </surface>
      </collision>
      <collision name='base_link_fixed_joint_lump__lidar_link_collision_2'>
        <pose>-0.06425 0.02885 0.035 1.57075 -0 0</pose>
        <geometry>
          <mesh>
            <scale>0.001 0.001 0.001</scale>
            <uri>file://$(find quadruped_robot)/stl/rplidar_main.STL</uri>
          </mesh>
        </geometry>
        <surface>
          <contact>
            <ode/>
          </contact>
          <friction>
            <ode/>
          </friction>
        </surface>
      </collision>
      <collision name='base_link_fixed_joint_lump__rear_link_collision_3'>
        <pose>-0.04 -0.06 -0.014 0 -0 0</pose>
        <geometry>
          <mesh>
            <scale>0.001 0.001 0.001</scale>
            <uri>file://$(find quadruped_robot)/stl/backpart.stl</uri>
          </mesh>
        </geometry>
        <surface>
          <contact>
            <ode/>
          </contact>
          <friction>
            <ode/>
          </friction>
        </surface>
      </collision>
      <visual name='base_link_visual'>
        <pose>-0.045 -0.06 -0.015 0 -0 0</pose>
        <geometry>
          <mesh>
            <scale>0.001 0.001 0.001</scale>
            <uri>file://$(find quadruped_robot)/stl/mainbody.stl</uri>
          </mesh>
        </geometry>
        <material>
          <script>
            <name>Gazebo/FlatBlack</name>
            <uri>file://media/materials/scripts/gazebo.material</uri>
          </script>
        </material>
      </visual>
      <visual name='base_link_fixed_joint_lump__front_link_visual_1'>
        <pose>-0.04 -0.06 -0.014 0 -0 0</pose>
        <geometry>
          <mesh>
            <scale>0.001 0.001 0.001</scale>
            <uri>file://$(find quadruped_robot)/stl/frontpart.stl</uri>
          </mesh>
        </geometry>
        <material>
          <script>
            <name>Gazebo/Yellow</name>
            <uri>file://media/materials/scripts/gazebo.material</uri>
          </script>
        </material>
      </visual>
      <visual name='base_link_fixed_joint_lump__lidar_link_visual_2'>
        <pose>-0.06425 0.02885 0.035 1.57075 -0 0</pose>
        <geometry>
          <mesh>
            <scale>0.001 0.001 0.001</scale>
            <uri>file://$(find quadruped_robot)/stl/rplidar_main.STL</uri>
          </mesh>
        </geometry>
        <material>
          <script>
            <name>Gazebo/Black</name>
            <uri>file://media/materials/scripts/gazebo.material</uri>
          </script>
        </material>
      </visual>
      <visual name='base_link_fixed_joint_lump__rear_link_visual_3'>
        <pose>-0.04 -0.06 -0.014 0 -0 0</pose>
        <geometry>
          <mesh>
            <scale>0.001 0.001 0.001</scale>
            <uri>file://$(find quadruped_robot)/stl/backpart.stl</uri>
          </mesh>
        </geometry>
        <material>
          <script>
            <name>Gazebo/Yellow</name>
            <uri>file://media/materials/scripts/gazebo.material</uri>
          </script>
        </material>
      </visual>
      <sensor name='sonar_1' type='ray'>
        <pose>-0.2 0.02 0 0 -0 3.14</pose>
        <always_on>1</always_on>
        <visualize>0</visualize>
        <update_rate>5</update_rate>
        <ray>
          <scan>
            <horizontal>
              <samples>5</samples>
              <resolution>1</resolution>
              <min_angle>-0.12</min_angle>
              <max_angle>0.12</max_angle>
            </horizontal>
            <vertical>
              <samples>5</samples>
              <resolution>1</resolution>
              <min_angle>-0.12</min_angle>
              <max_angle>0.12</max_angle>
            </vertical>
          </scan>
          <range>
            <min>0.02</min>
            <max>10</max>
            <resolution>0.01</resolution>
          </range>
          <noise>
            <type>gaussian</type>
            <mean>0</mean>
            <stddev>0.01</stddev>
          </noise>
        </ray>
        <plugin name='sonar_1' filename='libgazebo_ros_ray_sensor.so'>
          <ros>
            <remapping>~/out:=sonar_1</remapping>
          </ros>
          <output_type>sensor_msgs/Range</output_type>
          <radiation_type>ultrasound</radiation_type>
          <frame_name>base_link</frame_name>
        </plugin>
      </sensor>
      <sensor name='sonar_2' type='ray'>
        <pose>-0.2 -0.02 0 0 -0 3.14</pose>
        <always_on>1</always_on>
        <visualize>0</visualize>
        <update_rate>5</update_rate>
        <ray>
          <scan>
            <horizontal>
              <samples>5</samples>
              <resolution>1</resolution>
              <min_angle>-0.12</min_angle>
              <max_angle>0.12</max_angle>
            </horizontal>
            <vertical>
              <samples>5</samples>
              <resolution>1</resolution>
              <min_angle>-0.12</min_angle>
              <max_angle>0.12</max_angle>
            </vertical>
          </scan>
          <range>
            <min>0.02</min>
            <max>10</max>
            <resolution>0.01</resolution>
          </range>
          <noise>
            <type>gaussian</type>
            <mean>0</mean>
            <stddev>0.01</stddev>
          </noise>
        </ray>
        <plugin name='sonar_2' filename='libgazebo_ros_ray_sensor.so'>
          <ros>
            <remapping>~/out:=sonar_2</remapping>
          </ros>
          <output_type>sensor_msgs/Range</output_type>
          <radiation_type>ultrasound</radiation_type>
          <frame_name>base_link</frame_name>
        </plugin>
      </sensor>
      <sensor name='camera' type='camera'>
        <pose>-0.1 0 0 0 -0 3.14</pose>
        <camera>
          <horizontal_fov>1.047</horizontal_fov>
          <image>
            <width>640</width>
            <height>360</height>
            <format>R8G8B8</format>
          </image>
          <clip>
            <near>0.1</near>
            <far>100</far>
          </clip>
          <noise>
            <type>gaussian</type>
            <mean>0</mean>
            <stddev>0.005</stddev>
          </noise>
        </camera>
        <always_on>1</always_on>
        <update_rate>15</update_rate>
        <visualize>0</visualize>
        <plugin name='camera_plugin' filename='libgazebo_ros_camera.so'>
          <camera_name>camera</camera_name>
          <frame_name>base_link</frame_name>
          <hack_baseline>0.07</hack_baseline>
        </plugin>
      </sensor>
      <sensor name='hokuyo' type='ray'>
        <always_on>1</always_on>
        <update_rate>30</update_rate>
        <visualize>0</visualize>
        <ray>
          <scan>
            <horizontal>
              <samples>1040</samples>
              <resolution>1</resolution>
              <min_angle>2.26893</min_angle>
              <max_angle>-2.26893</max_angle>
            </horizontal>
          </scan>
          <range>
            <min>0.2</min>
            <max>30</max>
            <resolution>0.01</resolution>
          </range>
          <noise>
            <type>gaussian</type>
            <mean>0</mean>
            <stddev>0.004</stddev>
          </noise>
        </ray>
        <plugin name='gazebo_ros_hokuyo_controller' filename='libgazebo_ros_ray_sensor.so'>
          <ros>
            <namespace>lidar_link</namespace>
            <argument>~/out:=scan</argument>
          </ros>
          <output_type>sensor_msgs/LaserScan</output_type>
          <min_intensity>100.0</min_intensity>
        </plugin>
        <pose>0 0 0.035 0 -0 0</pose>
      </sensor>
      <sensor name='imu_controller' type='imu'>
        <always_on>1</always_on>
        <update_rate>50</update_rate>
        <plugin name='gazebo_ros_imu_sensor' filename='libgazebo_ros_imu_sensor.so'>
          <ros>
            <namespace>/imu</namespace>
            <argument>~/out:=data</argument>
          </ros>
          <updateRate>50.0</updateRate>
          <bodyName>imu_link</bodyName>
          <topicName>imu/data</topicName>
          <accelDrift>0.005 0.005 0.005</accelDrift>
          <accelGaussianNoise>0.005 0.005 0.005</accelGaussianNoise>
          <rateDrift>0.005 0.005 0.005</rateDrift>
          <rateGaussianNoise>0.005 0.005 0.005</rateGaussianNoise>
          <headingDrift>0.005</headingDrift>
          <headingGaussianNoise>0.005</headingGaussianNoise>
        </plugin>
        <pose>0 0 0 0 -0 0</pose>
      </sensor>
    </link>
    <joint name='front_left_shoulder' type='revolute'>
      <pose relative_to='base_link'>-0.093 -0.036 0 0 -0 0</pose>
      <parent>base_link</parent>
      <child>front_left_shoulder_link</child>
      <axis>
        <xyz>1 0 0</xyz>
        <limit>
          <lower>-3.14159</lower>
          <upper>3.14159</upper>
          <effort>25</effort>
          <velocity>1.5</velocity>
        </limit>
        <dynamics>
          <damping>0</damping>
          <friction>0.5</friction>
          <spring_reference>0</spring_reference>
          <spring_stiffness>0</spring_stiffness>
        </dynamics>
      </axis>
    </joint>
    <link name='front_left_shoulder_link'>
      <pose relative_to='front_left_shoulder'>0 0 0 0 -0 0</pose>
      <inertial>
        <pose>0 0 0 0 -0 0</pose>
        <mass>0.3</mass>
        <inertia>
          <ixx>0.0005</ixx>
          <ixy>0</ixy>
          <ixz>0</ixz>
          <iyy>0.0006</iyy>
          <iyz>0</iyz>
          <izz>0.0007</izz>
        </inertia>
      </inertial>
      <collision name='front_left_shoulder_link_collision'>
        <pose>-0.135 -0.02 -0.01 0 -0 0</pose>
        <geometry>
          <mesh>
            <scale>0.001 0.001 0.001</scale>
            <uri>file://$(find quadruped_robot)/stl/lshoulder.stl</uri>
          </mesh>
        </geometry>
        <surface>
          <contact>
            <ode/>
          </contact>
          <friction>
            <ode/>
          </friction>
        </surface>
      </collision>
      <visual name='front_left_shoulder_link_visual'>
        <pose>-0.135 -0.02 -0.01 0 -0 0</pose>
        <geometry>
          <mesh>
            <scale>0.001 0.001 0.001</scale>
            <uri>file://$(find quadruped_robot)/stl/lshoulder.stl</uri>
          </mesh>
        </geometry>
        <material>
          <script>
            <name>Gazebo/Black</name>
            <uri>file://media/materials/scripts/gazebo.material</uri>
          </script>
        </material>
      </visual>
    </link>
    <joint name='front_left_leg' type='revolute'>
      <pose relative_to='front_left_shoulder_link'>0 -0.052 0 0 -0 0</pose>
      <parent>front_left_shoulder_link</parent>
      <child>front_left_leg_link</child>
      <axis>
        <xyz>0 1 0</xyz>
        <limit>
          <lower>-3.14159</lower>
          <upper>3.14159</upper>
          <effort>25</effort>
          <velocity>1.5</velocity>
        </limit>
        <dynamics>
          <damping>0</damping>
          <friction>0</friction>
          <spring_reference>0</spring_reference>
          <spring_stiffness>0</spring_stiffness>
        </dynamics>
      </axis>
    </joint>
    <link name='front_left_leg_link'>
      <pose relative_to='front_left_leg'>0 0 0 0 -0 0</pose>
      <inertial>
        <pose>0 0 0 0 -0 0</pose>
        <mass>0.2</mass>
        <inertia>
          <ixx>0.0002</ixx>
          <ixy>0</ixy>
          <ixz>0</ixz>
          <iyy>0.0003</iyy>
          <iyz>0</iyz>
          <izz>0.0004</izz>
        </inertia>
      </inertial>
      <collision name='front_left_leg_link_collision'>
        <pose>-0.125 0.04 -0.02 0 -0 0</pose>
        <geometry>
          <mesh>
            <scale>0.001 0.001 0.001</scale>
            <uri>file://$(find quadruped_robot)/stl/larm.stl</uri>
          </mesh>
        </geometry>
        <surface>
          <contact>
            <ode/>
          </contact>
          <friction>
            <ode/>
          </friction>
        </surface>
      </collision>
      <visual name='front_left_leg_link_visual'>
        <pose>-0.125 0.04 -0.02 0 -0 0</pose>
        <geometry>
          <mesh>
            <scale>0.001 0.001 0.001</scale>
            <uri>file://$(find quadruped_robot)/stl/larm.stl</uri>
          </mesh>
        </geometry>
        <material>
          <script>
            <name>Gazebo/Black</name>
            <uri>file://media/materials/scripts/gazebo.material</uri>
          </script>
        </material>
      </visual>
      <visual name='front_left_leg_link_cover_visual_1'>
        <pose>-0.125 0.04 -0.02 0 -0 0</pose>
        <geometry>
          <mesh>
            <scale>0.001 0.001 0.001</scale>
            <uri>file://$(find quadruped_robot)/stl/larm_cover.stl</uri>
          </mesh>
        </geometry>
        <material>
          <script>
            <name>Gazebo/Black</name>
            <uri>file://media/materials/scripts/gazebo.material</uri>
          </script>
        </material>
      </visual>
    </link>
    <joint name='front_left_foot' type='revolute'>
      <pose relative_to='front_left_leg_link'>-0.01 0 -0.12 0 -0 0</pose>
      <parent>front_left_leg_link</parent>
      <child>front_left_foot_link</child>
      <axis>
        <xyz>0 1 0</xyz>
        <limit>
          <lower>-3.14159</lower>
          <upper>3.14159</upper>
          <effort>25</effort>
          <velocity>1.5</velocity>
        </limit>
        <dynamics>
          <damping>0</damping>
          <friction>0.5</friction>
          <spring_reference>0</spring_reference>
          <spring_stiffness>0</spring_stiffness>
        </dynamics>
      </axis>
    </joint>
    <link name='front_left_foot_link'>
      <pose relative_to='front_left_foot'>0 0 0 0 -0 0</pose>
      <inertial>
        <pose>0 0 -0.038333 0 -0 0</pose>
        <mass>0.15</mass>
        <inertia>
          <ixx>0.000590833</ixx>
          <ixy>0</ixy>
          <ixz>0</ixz>
          <iyy>0.000590833</iyy>
          <iyz>0</iyz>
          <izz>0.00015</izz>
        </inertia>
      </inertial>
      <collision name='front_left_foot_link_collision'>
        <pose>-0.12 0.04 0.1 0 -0 0</pose>
        <geometry>
          <mesh>
            <scale>0.001 0.001 0.001</scale>
            <uri>file://$(find quadruped_robot)/stl/lfoot.stl</uri>
          </mesh>
        </geometry>
        <surface>
          <contact>
            <ode>
              <kp>1e+10</kp>
              <kd>100</kd>
              <min_depth>0.05</min_depth>
            </ode>
          </contact>
          <friction>
            <ode>
              <mu>0.8</mu>
              <mu2>0.8</mu2>
            </ode>
          </friction>
        </surface>
      </collision>
      <collision name='front_left_foot_link_fixed_joint_lump__front_left_toe_link_collision_1'>
        <pose>0 -0.01 -0.115 0 -0.4001 0</pose>
        <geometry>
          <mesh>
            <scale>0.001 0.001 0.001</scale>
            <uri>file://$(find quadruped_robot)/stl/foot.stl</uri>
          </mesh>
        </geometry>
        <surface>
          <contact>
            <ode/>
          </contact>
          <friction>
            <ode/>
          </friction>
        </surface>
      </collision>
      <visual name='front_left_foot_link_visual'>
        <pose>-0.12 0.04 0.1 0 -0 0</pose>
        <geometry>
          <mesh>
            <scale>0.001 0.001 0.001</scale>
            <uri>file://$(find quadruped_robot)/stl/lfoot.stl</uri>
          </mesh>
        </geometry>
        <material>
          <script>
            <name>Gazebo/Black</name>
            <uri>file://media/materials/scripts/gazebo.material</uri>
          </script>
        </material>
      </visual>
      <visual name='front_left_foot_link_fixed_joint_lump__front_left_toe_link_visual_1'>
        <pose>0 -0.01 -0.115 0 -0.4001 0</pose>
        <geometry>
          <mesh>
            <scale>0.001 0.001 0.001</scale>
            <uri>file://$(find quadruped_robot)/stl/foot.stl</uri>
          </mesh>
        </geometry>
        <material>
          <script>
            <name>Gazebo/Grey</name>
            <uri>file://media/materials/scripts/gazebo.material</uri>
          </script>
        </material>
      </visual>
    </link>
    <joint name='front_right_shoulder' type='revolute'>
      <pose relative_to='base_link'>-0.093 0.036 0 0 -0 0</pose>
      <parent>base_link</parent>
      <child>front_right_shoulder_link</child>
      <axis>
        <xyz>1 0 0</xyz>
        <limit>
          <lower>-3.14159</lower>
          <upper>3.14159</upper>
          <effort>25</effort>
          <velocity>1.5</velocity>
        </limit>
        <dynamics>
          <damping>0</damping>
          <friction>0.5</friction>
          <spring_reference>0</spring_reference>
          <spring_stiffness>0</spring_stiffness>
        </dynamics>
      </axis>
    </joint>
    <link name='front_right_shoulder_link'>
      <pose relative_to='front_right_shoulder'>0 0 0 0 -0 0</pose>
      <inertial>
        <pose>0 0 0 0 -0 0</pose>
        <mass>0.3</mass>
        <inertia>
          <ixx>0.0005</ixx>
          <ixy>0</ixy>
          <ixz>0</ixz>
          <iyy>0.0006</iyy>
          <iyz>0</iyz>
          <izz>0.0007</izz>
        </inertia>
      </inertial>
      <collision name='front_right_shoulder_link_collision'>
        <pose>-0.135 -0.09 -0.01 0 -0 0</pose>
        <geometry>
          <mesh>
            <scale>0.001 0.001 0.001</scale>
            <uri>file://$(find quadruped_robot)/stl/rshoulder.stl</uri>
          </mesh>
        </geometry>
        <surface>
          <contact>
            <ode/>
          </contact>
          <friction>
            <ode/>
          </friction>
        </surface>
      </collision>
      <visual name='front_right_shoulder_link_visual'>
        <pose>-0.135 -0.09 -0.01 0 -0 0</pose>
        <geometry>
          <mesh>
            <scale>0.001 0.001 0.001</scale>
            <uri>file://$(find quadruped_robot)/stl/rshoulder.stl</uri>
          </mesh>
        </geometry>
        <material>
          <script>
            <name>Gazebo/Black</name>
            <uri>file://media/materials/scripts/gazebo.material</uri>
          </script>
        </material>
      </visual>
    </link>
    <joint name='front_right_leg' type='revolute'>
      <pose relative_to='front_right_shoulder_link'>0 0.052 0 0 -0 0</pose>
      <parent>front_right_shoulder_link</parent>
      <child>front_right_leg_link</child>
      <axis>
        <xyz>0 1 0</xyz>
        <limit>
          <lower>-3.14159</lower>
          <upper>3.14159</upper>
          <effort>25</effort>
          <velocity>1.5</velocity>
        </limit>
        <dynamics>
          <damping>0</damping>
          <friction>0</friction>
          <spring_reference>0</spring_reference>
          <spring_stiffness>0</spring_stiffness>
        </dynamics>
      </axis>
    </joint>
    <link name='front_right_leg_link'>
      <pose relative_to='front_right_leg'>0 0 0 0 -0 0</pose>
      <inertial>
        <pose>0 0 0 0 -0 0</pose>
        <mass>0.2</mass>
        <inertia>
          <ixx>0.0002</ixx>
          <ixy>0</ixy>
          <ixz>0</ixz>
          <iyy>0.0003</iyy>
          <iyz>0</iyz>
          <izz>0.0004</izz>
        </inertia>
      </inertial>
      <collision name='front_right_leg_link_collision'>
        <pose>-0.125 -0.15 -0.02 0 -0 0</pose>
        <geometry>
          <mesh>
            <scale>0.001 0.001 0.001</scale>
            <uri>file://$(find quadruped_robot)/stl/rarm.stl</uri>
          </mesh>
        </geometry>
        <surface>
          <contact>
            <ode/>
          </contact>
          <friction>
            <ode/>
          </friction>
        </surface>
      </collision>
      <visual name='front_right_leg_link_visual'>
        <pose>-0.125 -0.15 -0.02 0 -0 0</pose>
        <geometry>
          <mesh>
            <scale>0.001 0.001 0.001</scale>
            <uri>file://$(find quadruped_robot)/stl/rarm.stl</uri>
          </mesh>
        </geometry>
        <material>
          <script>
            <name>Gazebo/Black</name>
            <uri>file://media/materials/scripts/gazebo.material</uri>
          </script>
        </material>
      </visual>
      <visual name='front_right_leg_link_cover_visual_1'>
        <pose>-0.125 -0.15 -0.02 0 -0 0</pose>
        <geometry>
          <mesh>
            <scale>0.001 0.001 0.001</scale>
            <uri>file://$(find quadruped_robot)/stl/rarm_cover.stl</uri>
          </mesh>
        </geometry>
        <material>
          <script>
            <name>Gazebo/Black</name>
            <uri>file://media/materials/scripts/gazebo.material</uri>
          </script>
        </material>
      </visual>
    </link>
    <joint name='front_right_foot' type='revolute'>
      <pose relative_to='front_right_leg_link'>-0.01 0 -0.12 0 -0 0</pose>
      <parent>front_right_leg_link</parent>
      <child>front_right_foot_link</child>
      <axis>
        <xyz>0 1 0</xyz>
        <limit>
          <lower>-3.14159</lower>
          <upper>3.14159</upper>
          <effort>25</effort>
          <velocity>1.5</velocity>
        </limit>
        <dynamics>
          <damping>0</damping>
          <friction>0.5</friction>
          <spring_reference>0</spring_reference>
          <spring_stiffness>0</spring_stiffness>
        </dynamics>
      </axis>
    </joint>
    <link name='front_right_foot_link'>
      <pose relative_to='front_right_foot'>0 0 0 0 -0 0</pose>
      <inertial>
        <pose>0 0 -0.038333 0 -0 0</pose>
        <mass>0.15</mass>
        <inertia>
          <ixx>0.000590833</ixx>
          <ixy>0</ixy>
          <ixz>0</ixz>
          <iyy>0.000590833</iyy>
          <iyz>0</iyz>
          <izz>0.00015</izz>
        </inertia>
      </inertial>
      <collision name='front_right_foot_link_collision'>
        <pose>-0.12 -0.15 0.1 0 -0 0</pose>
        <geometry>
          <mesh>
            <scale>0.001 0.001 0.001</scale>
            <uri>file://$(find quadruped_robot)/stl/rfoot.stl</uri>
          </mesh>
        </geometry>
        <surface>
          <contact>
            <ode>
              <kp>1e+10</kp>
              <kd>100</kd>
              <min_depth>0.05</min_depth>
            </ode>
          </contact>
          <friction>
            <ode>
              <mu>0.8</mu>
              <mu2>0.8</mu2>
            </ode>
          </friction>
        </surface>
      </collision>
      <collision name='front_right_foot_link_fixed_joint_lump__front_right_toe_link_collision_1'>
        <pose>0 -0.01 -0.115 0 -0.4001 0</pose>
        <geometry>
          <mesh>
            <scale>0.001 0.001 0.001</scale>
            <uri>file://$(find quadruped_robot)/stl/foot.stl</uri>
          </mesh>
        </geometry>
        <surface>
          <contact>
            <ode/>
          </contact>
          <friction>
            <ode/>
          </friction>
        </surface>
      </collision>
      <visual name='front_right_foot_link_visual'>
        <pose>-0.12 -0.15 0.1 0 -0 0</pose>
        <geometry>
          <mesh>
            <scale>0.001 0.001 0.001</scale>
            <uri>file://$(find quadruped_robot)/stl/rfoot.stl</uri>
          </mesh>
        </geometry>
        <material>
          <script>
            <name>Gazebo/Black</name>
            <uri>file://media/materials/scripts/gazebo.material</uri>
          </script>
        </material>
      </visual>
      <visual name='front_right_foot_link_fixed_joint_lump__front_right_toe_link_visual_1'>
        <pose>0 -0.01 -0.115 0 -0.4001 0</pose>
        <geometry>
          <mesh>
            <scale>0.001 0.001 0.001</scale>
            <uri>file://$(find quadruped_robot)/stl/foot.stl</uri>
          </mesh>
        </geometry>
        <material>
          <script>
            <name>Gazebo/Grey</name>
            <uri>file://media/materials/scripts/gazebo.material</uri>
          </script>
        </material>
      </visual>
    </link>
    <joint name='rear_left_shoulder' type='revolute'>
      <pose relative_to='base_link'>0.093 -0.036 0 0 -0 0</pose>
      <parent>base_link</parent>
      <child>rear_left_shoulder_link</child>
      <axis>
        <xyz>1 0 0</xyz>
        <limit>
          <lower>-3.14159</lower>
          <upper>3.14159</upper>
          <effort>25</effort>
          <velocity>1.5</velocity>
        </limit>
        <dynamics>
          <damping>0</damping>
          <friction>0.5</friction>
          <spring_reference>0</spring_reference>
          <spring_stiffness>0</spring_stiffness>
        </dynamics>
      </axis>
    </joint>
    <link name='rear_left_shoulder_link'>
      <pose relative_to='rear_left_shoulder'>0 0 0 0 -0 0</pose>
      <inertial>
        <pose>0 0 0 0 -0 0</pose>
        <mass>0.3</mass>
        <inertia>
          <ixx>0.0005</ixx>
          <ixy>0</ixy>
          <ixz>0</ixz>
          <iyy>0.0006</iyy>
          <iyz>0</iyz>
          <izz>0.0007</izz>
        </inertia>
      </inertial>
      <collision name='rear_left_shoulder_link_collision'>
        <pose>-0.135 -0.02 -0.01 0 -0 0</pose>
        <geometry>
          <mesh>
            <scale>0.001 0.001 0.001</scale>
            <uri>file://$(find quadruped_robot)/stl/lshoulder.stl</uri>
          </mesh>
        </geometry>
        <surface>
          <contact>
            <ode/>
          </contact>
          <friction>
            <ode/>
          </friction>
        </surface>
      </collision>
      <visual name='rear_left_shoulder_link_visual'>
        <pose>-0.135 -0.02 -0.01 0 -0 0</pose>
        <geometry>
          <mesh>
            <scale>0.001 0.001 0.001</scale>
            <uri>file://$(find quadruped_robot)/stl/lshoulder.stl</uri>
          </mesh>
        </geometry>
        <material>
          <script>
            <name>Gazebo/Black</name>
            <uri>file://media/materials/scripts/gazebo.material</uri>
          </script>
        </material>
      </visual>
    </link>
    <joint name='rear_left_leg' type='revolute'>
      <pose relative_to='rear_left_shoulder_link'>0 -0.052 0 0 -0 0</pose>
      <parent>rear_left_shoulder_link</parent>
      <child>rear_left_leg_link</child>
      <axis>
        <xyz>0 1 0</xyz>
        <limit>
          <lower>-3.14159</lower>
          <upper>3.14159</upper>
          <effort>25</effort>
          <velocity>1.5</velocity>
        </limit>
        <dynamics>
          <damping>0</damping>
          <friction>0</friction>
          <spring_reference>0</spring_reference>
          <spring_stiffness>0</spring_stiffness>
        </dynamics>
      </axis>
    </joint>
    <link name='rear_left_leg_link'>
      <pose relative_to='rear_left_leg'>0 0 0 0 -0 0</pose>
      <inertial>
        <pose>0 0 0 0 -0 0</pose>
        <mass>0.2</mass>
        <inertia>
          <ixx>0.0002</ixx>
          <ixy>0</ixy>
          <ixz>0</ixz>
          <iyy>0.0003</iyy>
          <iyz>0</iyz>
          <izz>0.0004</izz>
        </inertia>
      </inertial>
      <collision name='rear_left_leg_link_collision'>
        <pose>-0.125 0.04 -0.02 0 -0 0</pose>
        <geometry>
          <mesh>
            <scale>0.001 0.001 0.001</scale>
            <uri>file://$(find quadruped_robot)/stl/larm.stl</uri>
          </mesh>
        </geometry>
        <surface>
          <contact>
            <ode/>
          </contact>
          <friction>
            <ode/>
          </friction>
        </surface>
      </collision>
      <visual name='rear_left_leg_link_visual'>
        <pose>-0.125 0.04 -0.02 0 -0 0</pose>
        <geometry>
          <mesh>
            <scale>0.001 0.001 0.001</scale>
            <uri>file://$(find quadruped_robot)/stl/larm.stl</uri>
          </mesh>
        </geometry>
        <material>
          <script>
            <name>Gazebo/Black</name>
            <uri>file://media/materials/scripts/gazebo.material</uri>
          </script>
        </material>
      </visual>
      <visual name='rear_left_leg_link_cover_visual_1'>
        <pose>-0.125 0.04 -0.02 0 -0 0</pose>
        <geometry>
          <mesh>
            <scale>0.001 0.001 0.001</scale>
            <uri>file://$(find quadruped_robot)/stl/larm_cover.stl</uri>
          </mesh>
        </geometry>
        <material>
          <script>
            <name>Gazebo/Black</name>
            <uri>file://media/materials/scripts/gazebo.material</uri>
          </script>
        </material>
      </visual>
    </link>
    <joint name='rear_left_foot' type='revolute'>
      <pose relative_to='rear_left_leg_link'>-0.01 0 -0.12 0 -0 0</pose>
      <parent>rear_left_leg_link</parent>
      <child>rear_left_foot_link</child>
      <axis>
        <xyz>0 1 0</xyz>
        <limit>
          <lower>-3.14159</lower>
          <upper>3.14159</upper>
          <effort>25</effort>
          <velocity>1.5</velocity>
        </limit>
        <dynamics>
          <damping>0</damping>
          <friction>0.5</friction>
          <spring_reference>0</spring_reference>
          <spring_stiffness>0</spring_stiffness>
        </dynamics>
      </axis>
    </joint>
    <link name='rear_left_foot_link'>
      <pose relative_to='rear_left_foot'>0 0 0 0 -0 0</pose>
      <inertial>
        <pose>0 0 -0.038333 0 -0 0</pose>
        <mass>0.15</mass>
        <inertia>
          <ixx>0.000590833</ixx>
          <ixy>0</ixy>
          <ixz>0</ixz>
          <iyy>0.000590833</iyy>
          <iyz>0</iyz>
          <izz>0.00015</izz>
        </inertia>
      </inertial>
      <collision name='rear_left_foot_link_collision'>
        <pose>-0.12 0.04 0.1 0 -0 0</pose>
        <geometry>
          <mesh>
            <scale>0.001 0.001 0.001</scale>
            <uri>file://$(find quadruped_robot)/stl/lfoot.stl</uri>
          </mesh>
        </geometry>
        <surface>
          <contact>
            <ode>
              <kp>1e+10</kp>
              <kd>100</kd>
              <min_depth>0.05</min_depth>
            </ode>
          </contact>
          <friction>
            <ode>
              <mu>0.8</mu>
              <mu2>0.8</mu2>
            </ode>
          </friction>
        </surface>
      </collision>
      <collision name='rear_left_foot_link_fixed_joint_lump__rear_left_toe_link_collision_1'>
        <pose>0 -0.01 -0.115 0 -0.4001 0</pose>
        <geometry>
          <mesh>
            <scale>0.001 0.001 0.001</scale>
            <uri>file://$(find quadruped_robot)/stl/foot.stl</uri>
          </mesh>
        </geometry>
        <surface>
          <contact>
            <ode/>
          </contact>
          <friction>
            <ode/>
          </friction>
        </surface>
      </collision>
      <visual name='rear_left_foot_link_visual'>
        <pose>-0.12 0.04 0.1 0 -0 0</pose>
        <geometry>
          <mesh>
            <scale>0.001 0.001 0.001</scale>
            <uri>file://$(find quadruped_robot)/stl/lfoot.stl</uri>
          </mesh>
        </geometry>
        <material>
          <script>
            <name>Gazebo/Black</name>
            <uri>file://media/materials/scripts/gazebo.material</uri>
          </script>
        </material>
      </visual>
      <visual name='rear_left_foot_link_fixed_joint_lump__rear_left_toe_link_visual_1'>
        <pose>0 -0.01 -0.115 0 -0.4001 0</pose>
        <geometry>
          <mesh>
            <scale>0.001 0.001 0.001</scale>
            <uri>file://$(find quadruped_robot)/stl/foot.stl</uri>
          </mesh>
        </geometry>
        <material>
          <script>
            <name>Gazebo/Grey</name>
            <uri>file://media/materials/scripts/gazebo.material</uri>
          </script>
        </material>
      </visual>
    </link>
    <joint name='rear_right_shoulder' type='revolute'>
      <pose relative_to='base_link'>0.093 0.036 0 0 -0 0</pose>
      <parent>base_link</parent>
      <child>rear_right_shoulder_link</child>
      <axis>
        <xyz>1 0 0</xyz>
        <limit>
          <lower>-3.14159</lower>
          <upper>3.14159</upper>
          <effort>25</effort>
          <velocity>1.5</velocity>
        </limit>
        <dynamics>
          <damping>0</damping>
          <friction>0.5</friction>
          <spring_reference>0</spring_reference>
          <spring_stiffness>0</spring_stiffness>
        </dynamics>
      </axis>
    </joint>
    <link name='rear_right_shoulder_link'>
      <pose relative_to='rear_right_shoulder'>0 0 0 0 -0 0</pose>
      <inertial>
        <pose>0 0 0 0 -0 0</pose>
        <mass>0.3</mass>
        <inertia>
          <ixx>0.0005</ixx>
          <ixy>0</ixy>
          <ixz>0</ixz>
          <iyy>0.0006</iyy>
          <iyz>0</iyz>
          <izz>0.0007</izz>
        </inertia>
      </inertial>
      <collision name='rear_right_shoulder_link_collision'>
        <pose>-0.135 -0.09 -0.01 0 -0 0</pose>
        <geometry>
          <mesh>
            <scale>0.001 0.001 0.001</scale>
            <uri>file://$(find quadruped_robot)/stl/rshoulder.stl</uri>
          </mesh>
        </geometry>
        <surface>
          <contact>
            <ode/>
          </contact>
          <friction>
            <ode/>
          </friction>
        </surface>
      </collision>
      <visual name='rear_right_shoulder_link_visual'>
        <pose>-0.135 -0.09 -0.01 0 -0 0</pose>
        <geometry>
          <mesh>
            <scale>0.001 0.001 0.001</scale>
            <uri>file://$(find quadruped_robot)/stl/rshoulder.stl</uri>
          </mesh>
        </geometry>
        <material>
          <script>
            <name>Gazebo/Black</name>
            <uri>file://media/materials/scripts/gazebo.material</uri>
          </script>
        </material>
      </visual>
    </link>
    <joint name='rear_right_leg' type='revolute'>
      <pose relative_to='rear_right_shoulder_link'>0 0.052 0 0 -0 0</pose>
      <parent>rear_right_shoulder_link</parent>
      <child>rear_right_leg_link</child>
      <axis>
        <xyz>0 1 0</xyz>
        <limit>
          <lower>-3.14159</lower>
          <upper>3.14159</upper>
          <effort>25</effort>
          <velocity>1.5</velocity>
        </limit>
        <dynamics>
          <damping>0</damping>
          <friction>0</friction>
          <spring_reference>0</spring_reference>
          <spring_stiffness>0</spring_stiffness>
        </dynamics>
      </axis>
    </joint>
    <link name='rear_right_leg_link'>
      <pose relative_to='rear_right_leg'>0 0 0 0 -0 0</pose>
      <inertial>
        <pose>0 0 0 0 -0 0</pose>
        <mass>0.2</mass>
        <inertia>
          <ixx>0.0002</ixx>
          <ixy>0</ixy>
          <ixz>0</ixz>
          <iyy>0.0003</iyy>
          <iyz>0</iyz>
          <izz>0.0004</izz>
        </inertia>
      </inertial>
      <collision name='rear_right_leg_link_collision'>
        <pose>-0.125 -0.15 -0.02 0 -0 0</pose>
        <geometry>
          <mesh>
            <scale>0.001 0.001 0.001</scale>
            <uri>file://$(find quadruped_robot)/stl/rarm.stl</uri>
          </mesh>
        </geometry>
        <surface>
          <contact>
            <ode/>
          </contact>
          <friction>
            <ode/>
          </friction>
        </surface>
      </collision>
      <visual name='rear_right_leg_link_visual'>
        <pose>-0.125 -0.15 -0.02 0 -0 0</pose>
        <geometry>
          <mesh>
            <scale>0.001 0.001 0.001</scale>
            <uri>file://$(find quadruped_robot)/stl/rarm.stl</uri>
          </mesh>
        </geometry>
        <material>
          <script>
            <name>Gazebo/Black</name>
            <uri>file://media/materials/scripts/gazebo.material</uri>
          </script>
        </material>
      </visual>
      <visual name='rear_right_leg_link_cover_visual_1'>
        <pose>-0.125 -0.15 -0.02 0 -0 0</pose>
        <geometry>
          <mesh>
            <scale>0.001 0.001 0.001</scale>
            <uri>file://$(find quadruped_robot)/stl/rarm_cover.stl</uri>
          </mesh>
        </geometry>
        <material>
          <script>
            <name>Gazebo/Black</name>
            <uri>file://media/materials/scripts/gazebo.material</uri>
          </script>
        </material>
      </visual>
    </link>
    <joint name='rear_right_foot' type='revolute'>
      <pose relative_to='rear_right_leg_link'>-0.01 0 -0.12 0 -0 0</pose>
      <parent>rear_right_leg_link</parent>
      <child>rear_right_foot_link</child>
      <axis>
        <xyz>0 1 0</xyz>
        <limit>
          <lower>-3.14159</lower>
          <upper>3.14159</upper>
          <effort>25</effort>
          <velocity>1.5</velocity>
        </limit>
        <dynamics>
          <damping>0</damping>
          <friction>0.5</friction>
          <spring_reference>0</spring_reference>
          <spring_stiffness>0</spring_stiffness>
        </dynamics>
      </axis>
    </joint>
    <link name='rear_right_foot_link'>
      <pose relative_to='rear_right_foot'>0 0 0 0 -0 0</pose>
      <inertial>
        <pose>0 0 -0.038333 0 -0 0</pose>
        <mass>0.15</mass>
        <inertia>
          <ixx>0.000590833</ixx>
          <ixy>0</ixy>
          <ixz>0</ixz>
          <iyy>0.000590833</iyy>
          <iyz>0</iyz>
          <izz>0.00015</izz>
        </inertia>
      </inertial>
      <collision name='rear_right_foot_link_collision'>
        <pose>-0.12 -0.15 0.1 0 -0 0</pose>
        <geometry>
          <mesh>
            <scale>0.001 0.001 0.001</scale>
            <uri>file://$(find quadruped_robot)/stl/rfoot.stl</uri>
          </mesh>
        </geometry>
        <surface>
          <contact>
            <ode>
              <kp>1e+10</kp>
              <kd>100</kd>
              <min_depth>0.05</min_depth>
            </ode>
          </contact>
          <friction>
            <ode>
              <mu>0.8</mu>
              <mu2>0.8</mu2>
            </ode>
          </friction>
        </surface>
      </collision>
      <collision name='rear_right_foot_link_fixed_joint_lump__rear_right_toe_link_collision_1'>
        <pose>0 -0.01 -0.115 0 -0.4001 0</pose>
        <geometry>
          <mesh>
            <scale>0.001 0.001 0.001</scale>
            <uri>file://$(find quadruped_robot)/stl/foot.stl</uri>
          </mesh>
        </geometry>
        <surface>
          <contact>
            <ode/>
          </contact>
          <friction>
            <ode/>
          </friction>
        </surface>
      </collision>
      <visual name='rear_right_foot_link_visual'>
        <pose>-0.12 -0.15 0.1 0 -0 0</pose>
        <geometry>
          <mesh>
            <scale>0.001 0.001 0.001</scale>
            <uri>file://$(find quadruped_robot)/stl/rfoot.stl</uri>
          </mesh>
        </geometry>
        <material>
          <script>
            <name>Gazebo/Black</name>
            <uri>file://media/materials/scripts/gazebo.material</uri>
          </script>
        </material>
      </visual>
      <visual name='rear_right_foot_link_fixed_joint_lump__rear_right_toe_link_visual_1'>
        <pose>0 -0.01 -0.115 0 -0.4001 0</pose>
        <geometry>
          <mesh>
            <scale>0.001 0.001 0.001</scale>
            <uri>file://$(find quadruped_robot)/stl/foot.stl</uri>
          </mesh>
        </geometry>
        <material>
          <script>
            <name>Gazebo/Grey</name>
            <uri>file://media/materials/scripts/gazebo.material</uri>
          </script>
        </material>
      </visual>
    </link>
    <plugin name='p3d_base_controller' filename='libgazebo_ros_p3d.so'>
      <ros>
        <namespace/>
        <argument>odom:=odom/ground_truth</argument>
      </ros>
      <body_name>base_link</body_name>
      <frame_name>world</frame_name>
      <update_rate>10.0</update_rate>
      <xyz_offset>0 0 0</xyz_offset>
      <rpy_offset>0 0 0</rpy_offset>
      <gaussian_noise>0.01</gaussian_noise>
    </plugin>
    <static>0</static>
    <plugin name='gazebo_ros2_control' filename='libgazebo_ros2_control.so'>
      <parameters>$(find quadruped_robot)/config/spot_control.yaml</parameters>
    </plugin>
  </model>
</sdf>
